<?xml version="1.0"?>
<robot name="fanuc_lrmate200id7l" xmlns:xacro="http://ros.org/wiki/xacro">

    <xacro:include filename="$(find fanuc_resources)/urdf/common_materials.xacro" />

    <link name="link_0">
        <visual>
            <origin xyz="0 0 0" rpy="0 0 0" />
            <geometry>
                <mesh
                    filename="package://fanuc_lrmate200id_support/meshes/lrmate200id/visual/base_link.stl" />
            </geometry>
            <xacro:material_fanuc_gray28 />
        </visual>
        <collision>
            <origin xyz="0 0 0" rpy="0 0 0" />
            <geometry>
                <mesh
                    filename="package://fanuc_lrmate200id_support/meshes/lrmate200id/collision/base_link.stl" />
            </geometry>
        </collision>
    </link>

    <joint name="joint_1" type="revolute">
        <origin xyz="0 0 0.330" rpy="0 0 0" />
        <parent link="link_0" />
        <child link="link_1" />
        <axis xyz="0 0 1" />
        <limit effort="0" lower="-2.96706" upper="2.96706" velocity="6.45771" />
    </joint>

    <link name="link_1">
        <visual>
            <origin xyz="0 0 0" rpy="0 0 0" />
            <geometry>
                <mesh
                    filename="package://fanuc_lrmate200id_support/meshes/lrmate200id/visual/link_1.stl" />
            </geometry>
            <xacro:material_fanuc_yellow />
        </visual>
        <collision>
            <origin xyz="0 0 0" rpy="0 0 0" />
            <geometry>
                <mesh
                    filename="package://fanuc_lrmate200id_support/meshes/lrmate200id/collision/link_1.stl" />
            </geometry>
        </collision>
    </link>

    <joint name="joint_2" type="revolute">
        <origin xyz="0.050 0 0" rpy="0 0 0" />
        <parent link="link_1" />
        <child link="link_2" />
        <axis xyz="0 1 0" />
        <limit effort="0" lower="-1.74533" upper="2.53073" velocity="5.41052" />
    </joint>

    <link name="link_2">
        <visual>
            <origin xyz="0 0 0" rpy="0 0 0" />
            <geometry>
                <mesh
                    filename="package://fanuc_lrmate200id_support/meshes/lrmate200id7l/visual/link_2.stl" />
            </geometry>
            <xacro:material_fanuc_yellow />
        </visual>
        <collision>
            <origin xyz="0 0 0" rpy="0 0 0" />
            <geometry>
                <mesh
                    filename="package://fanuc_lrmate200id_support/meshes/lrmate200id7l/collision/link_2.stl" />
            </geometry>
        </collision>
    </link>

    <joint name="joint_3" type="revolute">
        <origin xyz="0 0 0.440" rpy="0 0 0" />
        <parent link="link_2" />
        <child link="link_3" />
        <axis xyz="0 -1 0" />
        <limit effort="0" lower="-1.22173" upper="3.71755" velocity="7.15585" />
    </joint>

    <link name="link_3">
        <visual>
            <origin xyz="0 0 0" rpy="0 0 0" />
            <geometry>
                <mesh
                    filename="package://fanuc_lrmate200id_support/meshes/lrmate200id/visual/link_3.stl" />
            </geometry>
            <xacro:material_fanuc_yellow />
        </visual>
        <collision>
            <origin xyz="0 0 0" rpy="0 0 0" />
            <geometry>
                <mesh
                    filename="package://fanuc_lrmate200id_support/meshes/lrmate200id/collision/link_3.stl" />
            </geometry>
        </collision>
    </link>

    <joint name="joint_4" type="revolute">
        <origin xyz="0 0 0.035" rpy="0 0 0" />
        <parent link="link_3" />
        <child link="link_4" />
        <axis xyz="-1 0 0" />
        <limit effort="0" lower="-3.31613" upper="3.31613" velocity="9.59931" />
    </joint>

    <link name="link_4">
        <visual>
            <origin xyz="0 0 0" rpy="0 0 0" />
            <geometry>
                <mesh
                    filename="package://fanuc_lrmate200id_support/meshes/lrmate200id7l/visual/link_4.stl" />
            </geometry>
            <xacro:material_fanuc_yellow />
        </visual>
        <collision>
            <origin xyz="0 0 0" rpy="0 0 0" />
            <geometry>
                <mesh
                    filename="package://fanuc_lrmate200id_support/meshes/lrmate200id7l/collision/link_4.stl" />
            </geometry>
        </collision>
    </link>

    <joint name="joint_5" type="revolute">
        <origin xyz="0.420 0 0" rpy="0 0 0" />
        <parent link="link_4" />
        <child link="link_5" />
        <axis xyz="0 -1 0" />
        <limit effort="0" lower="-2.18166" upper="2.18166"
            velocity="9.51204" />
    </joint>

    <link name="link_5">
        <visual>
            <origin xyz="0 0 0" rpy="0 0 0" />
            <geometry>
                <mesh
                    filename="package://fanuc_lrmate200id_support/meshes/lrmate200id/visual/link_5.stl" />
            </geometry>
            <xacro:material_fanuc_yellow />
        </visual>
        <collision>
            <origin xyz="0 0 0" rpy="0 0 0" />
            <geometry>
                <mesh
                    filename="package://fanuc_lrmate200id_support/meshes/lrmate200id/collision/link_5.stl" />
            </geometry>
        </collision>
    </link>

    <joint name="joint_6" type="revolute">
        <origin xyz="0.080 0 0" rpy="0 0 0" />
        <parent link="link_5" />
        <child link="link_6" />
        <axis xyz="-1 0 0" />
        <limit effort="0" lower="-6.28319" upper="6.28319"
            velocity="17.4533" />
    </joint>

    <link name="link_6">
        <visual>
            <origin xyz="0 0 0" rpy="0 0 0" />
            <geometry>
                <mesh
                    filename="package://fanuc_lrmate200id_support/meshes/lrmate200id/visual/link_6.stl" />
            </geometry>
            <xacro:material_fanuc_black />
        </visual>
        <collision>
            <origin xyz="0 0 0" rpy="0 0 0" />
            <geometry>
                <mesh
                    filename="package://fanuc_lrmate200id_support/meshes/lrmate200id/collision/link_6.stl" />
            </geometry>
        </collision>
    </link>

    <joint name="link_6_flange" type="fixed">
        <origin xyz="0 0 0" rpy="0 0 0" />
        <parent link="link_6" />
        <child link="flange" />
    </joint>

    <link name="flange" />

    <joint name="flange_tool" type="fixed">
        <origin xyz="0 0 0" rpy="0 0 0" />
        <parent link="flange" />
        <child link="tool" />
    </joint>

    <link name="tool">
        <collision>
            <origin xyz="0.065 0 0" rpy="0 0 0" />
            <geometry>
                <box size="0.13 0.028 0.045" />
            </geometry>
        </collision>
        <visual>
            <origin xyz="0.065 0 0" rpy="0 0 0" />
            <geometry>
                <box size="0.13 0.028 0.045" />
            </geometry>
        </visual>
    </link>

    <joint name="tool_leftfinger" type="prismatic">
        <origin xyz="0.130 0 0.035" rpy="0 0 0" />
        <parent link="tool" />
        <child link="leftfinger" />
        <axis xyz="0 0 1" />
        <limit effort="100" lower="-0.0035" upper="0" velocity="0.2" />
    </joint>

    <link name="leftfinger">
        <collision>
            <origin xyz="0.015 0 0.0015" rpy="0 0 0" />
            <geometry>
                <box size="0.03 0.053 0.003" />
            </geometry>
        </collision>
        <visual>
            <origin xyz="0.015 0 0.0015" rpy="0 0 0" />
            <geometry>
                <box size="0.03 0.053 0.003" />
            </geometry>
        </visual>
    </link>

    <joint name="tool_rightfinger" type="prismatic">
        <origin xyz="0.130 0 -0.035" rpy="0 0 0" />
        <parent link="tool" />
        <child link="rightfinger" />
        <axis xyz="0 0 1" />
        <limit effort="100" lower="0.0" upper="0.0035" velocity="0.2" />
    </joint>

    <link name="rightfinger">
        <collision>
            <origin xyz="0.015 0 -0.0015" rpy="0 0 0" />
            <geometry>
                <box size="0.03 0.053 0.003" />
            </geometry>
        </collision>
        <visual>
            <origin xyz="0.015 0 -0.0015" rpy="0 0 0" />
            <geometry>
                <box size="0.03 0.053 0.003" />
            </geometry>
        </visual>
    </link>

    <joint name="flange_TCP" type="fixed">
        <origin xyz="0.138 0 0" rpy="0 0 0" />
        <parent link="flange" />
        <child link="TCP" />
    </joint>

    <link name="TCP" />

</robot>